Workbook

Sheet studies
A1: Authors | B1: No. of samples (replicates) | C1: Recovery methods | D1: Equipment tested | E1: Biological material | F1: Substrate type | G1: Substrate descriptions | H1: Statistical analysis | I1: STR analysis | J1: Results | K1: Key TL= tape-lift SS = single swabbing SWS = single wet swabbing DWS = double wet swabbing NS = nylon swab CS = cotton swab SS = single swab technique DS = double swab technique SAT = small autosomal target LAT = large autosomal target PLS = Pulse lavage system | L1: Instructions Use the drop down buttons to filter results via the variables you are interested in to find relevent research articles. | M1: Replicates ≥ 10. | N1: Replicates < 10 > 3 | O1: Replicates ≤3, or statistical analysis not performed. | P1: comparison_count
A2: Abdullah et al., 2023 | B2: 100 (3 to 5) | C2: Swabbing techniques. | D2: Cotton tipped swab (150C, Copan). Wet-moist, wet-wet and wet-dry, (DS), moist-dry and wet (SS) techniques. | E2: Human blood (10 µL of DNA 2.22 - 3.07 ng/µL). | F2: Porous Non-porous | G2: 100% cotton (Spotlight). Porcelain tiles. | H2: Yes | I2: No | J2: Wet-moist double swabbing for 30 s produced significantly higher DNA yield from the cotton substrate (p < 0.01). Swabbing duration for tile did not affect DNA yield, nor did SS v DS method. | P2: =COUNTIF(Comparisons!$A:$A,A2)
A3: Biggin et al., 2022 | B3: 40 (10) | C3: Swabbing. FTA paper-scraping. Untreated filter paper. | D3: Puritan Cap-Shure 6′′ sterile cotton swab. Cytiva Whatman™, (Marlborough, MA, USA). | E3: Human blood (neat). | F3: Porous | G3: Snow. | H3: Not performed | I3: Yes | J3: All methods produced full STR profiles. DNA mean yields & Degradation Index per method: Swabs: 3.573 ng/µL. DI = 0.733. Filter paper: 28.01 ng/µL. DI = 0.599. FTA: 5.439 ng/µL. DI = 0.683. No statistical analyses, although there is enough data to perform, and the filter paper had the highest DNA yield. | P3: =COUNTIF(Comparisons!$A:$A,A3)
A4: Blackmore et al., 2024 | B4: 75 (1 to 3) (11) | C4: Tape-lifting. Swabbing. Vacuum. | D4: EO treated tape lift kit (Lovell Surgical So­ lutions, AUS) . EO treated Rayon swab (Medical Wire & Equipment, UK). M-Vac®. | E4: Saliva (1:40 & 1:160) Touch DNA | F4: Porous Non-porous | G4: 100% polypropylene carpet, T-shirt (submerged in a creek for 5 days), car boot carpet, brick. | H4: Yes | I4: Yes | J4: STR profiling was performed for samples with the closest mean SAT for each collection method. Discrepancies found between DNA yield from the SAT and amplified alleles. Saliva: Carpet: 1:40 dilution = TL Carpet:1:160 dilution = M-Vac® Brick: 1:40 dilution = TL (amp. 11 alleles) Touch DNA: Car boot = TL T-shirt = M-Vac® | P4: =COUNTIF(Comparisons!$A:$A,A4)
A5: Bonsu et al., 2021a | B5: 50 (5) | C5: Swabbing. | D5: Isohelix™ (Cell Projects Ltd., Harrietsham, United Kingdom). Rayon (Puritan, Guilford, USA). DS (both moist) technique. | E5: gDNA 20 ng (10 µL of 2 ng/µL). | F5: Non-porous | G5: Brass, copper, steel. plastic | H5: Yes | I5: No | J5: Isohelix™ was significantly more efficient for DNA recovery from all substrates (74% DNA recovery compared to 50% for the Puritan Rayon). | P5: =COUNTIF(Comparisons!$A:$A,A5)
A6: Bonsu et al., 2021b | B6: 10 (1) | C6: Swabbing. | D6: Isohelix™ (Cell Projects Ltd., Harrietsham, United Kingdom). Rayon (Puritan, Guilford, USA). SS (wet) technique. | E6: Touch DNA | F6: Non-porous | G6: Brass, aluminium bathroom door, aluminium office door. Stainless steel tap. Plastic soap dispenser (control). | H6: Yes | I6: Yes | J6: The Isohelix™ swab recovered significantly more DNA than the Puritan Rayon swab for all metals except the aluminium office door handle. More contributors and higher RFU values were observed with the Isohelix™ swab. | P6: =COUNTIF(Comparisons!$A:$A,A6)
A7: Bright & Petricevic, 2004 | B7: 56 (3) | C7: Tape-lifting. Swabbing. Soaking. | D7: Brands not reported. Double swab technique. | E7: Touch DNA | F7: Porous | G7: Shoe insoles. | H7: Not performed | I7: Yes | J7: TL recovered equal to higher DNA yields which were visibly cleaner than the swab or soak methods. Successful profiles were obtained from TL. More were viable from synthetic insoles than leather. Did not profile swab or soaks - only assessed the quantity of DNA. | P7: =COUNTIF(Comparisons!$A:$A,A7)
A8: Bruijns et al., 2018 | B8: 113 (3, 5 & 10) | C8: Swabbing. | D8: Deltalab cotton EUROTUBO®, Copan nylon flocked eSwab™, MWE rayon Transwab®, MWE rayon Dryswab®, APTACA rayon Transport swab, Texwipe nylon MicroSwab™, Texwipe polyester Absorbond®, Texwipe foam CleanFoam®, Texwipe polyester Honeycomb, Texwipe polyester Alpha®, Texwipe polyester Large Alpha®, Copan 4N6FLOQSwab® (buccal), Copan 4N6FLOQSwab® (Crime scene), Puritan® polyurethane foam tipped. | E8: Saliva (20 µL DNA isolate) | F8: n/a | G8: Absorption and extraction efficiency of each swab tested only. | H8: Not performed | I8: No | J8: Nylon flocked 4N6FLOQSwab™ (buccal) had the best recovery and release efficiency overall. No swab efficiency surpassed 50%. | P8: =COUNTIF(Comparisons!$A:$A,A8)
A9: Burmuzoska et al., 2022 | B9: 120 (5) | C9: Tape-lifting. Swabbing. | D9: 3 M tape (Lovell Surgical Solutions Pty. Ltd., Australia). Rayon swabs (Medical Wire & Equipment, UK). | E9: Saliva 1:50, 1:100 & 1:200 | F9: Porous Non-porous | G9: Porous: cotton, denim, polyester. Non-porous: tile, brass and synthetic leather. | H9: Yes | I9: Yes | J9: TL is more efficient for porous surfaces as higher DNA yields and more alleles were detected for both dilutions. Both methods are similar for non-porous surfaces. 1:50 dilution: TL significantly higher DNA yield for cotton and polyester. The denim result was not significant, possibly due to the high variability in results. Similar results for each method for non-porous substrates. 1:100 dilution: TL significantly higher DNA yield for polyester and denim. Swabbing was significantly higher for the tile. | P9: =COUNTIF(Comparisons!$A:$A,A9)
A10: Cahill & Chapman, 2020 | B10: 96 (4 & 5) | C10: Swabbing. Plasti dip. | D10: FLOQSwab® (Item code 502CS01, COPAN Brescia, ITA), foam Catch-All™ Sample Collection Swabs (EPICENTRE Wisconsin, USA) and COPAN® rayon plastic shaft swabs (Item code 8155CIS, COPAN Brescia, ITA). Plasti dip® | E10: Saliva | F10: Porous | G10: Brick. | H10: Yes | I10: Yes | J10: Some DNA profiles did not generate any alleles, even though DNA yields were quantified. 1000 cells, no statistical difference between methods. 10,000 cells, no statistical significance was observed between all swab types and the spray-on rubber. Except for the Large Autosomal Target (LAT). 20,000 cells, the spray-on rubber coating recovered a significantly higher concentration than all swab types (of small & large autosomal targets). | P10: =COUNTIF(Comparisons!$A:$A,A10)
A11: Chaudhry & Kavlick, 2023 | B11: 168 (6) | C11: Vacuum. | D11: Pulse Lavage systems (PLS): 1) Interpulse® handpiece with fan spray tip (Stryker Corp., Kalamazoo, MI) 2) Pulsavac® Plus handpiece with the high-capacity tibial plateau brush tip (Zimmer Surgical, Inc., Dover, OH) 3) Pulsavac® Plus handpiece with the shower tip (Zimmer Surgical, Inc.) 4) M-Vac® forensic wet-vacuum system (M-Vac® Systems, Inc.) | E11: Human blood | F11: Porous Non-porous | G11: Automotive trunk liner (Polymat, LLC., Belleville, MI), semi-gloss painted drywall (PPG Industries, Cleveland, OH; USG corporation, Chicago, IL), pressure-treated pine wood (UFP Industries, Inc., Grand Rapids, MI), medium-pile carpet (Shaw Industries Group, Inc., Dalton, GA), cotton bedsheet (Wamsutta Home Products, New York, NY), polypropylene rope with ¾ in. diameter (International Marketing Systems, Ltd., Fargo, ND). Control: plate glass. | H11: Yes | I11: No | J11: The fan spray tip recovered equal to higher DNA than the M-Vac for most samples (5/7) which was significant for the gloss painted wall. The brush tip recovered more DNA for 3/7 substrates, significantly higher for the rope and drywall. The shower tip recovered comparable DNA yields on 4/7 substrates. Authors suggest the PLS system is a viable alternative to the wet-vacuum due to comparable DNA yields and cost-effectiveness on substrates where swabbing may have failed to recover sufficient DNA for profiling. | P11: =COUNTIF(Comparisons!$A:$A,A11)
A12: Czado et al., 2024 | B12: 110 (10) | C12: Swabbing. Soaking. Direct PCR. | D12: Nylon swabs with 30 µL water, cotton DS with 30 µL water, cotton DS with 30 µL 0.5 M EDTA. rinse/swab with BTMix. Direct PCR: microFLOQ® direct swabs (COPAN Diagnostics Inc., Murrietta, CA) + 1µL water. Recovery methods and two automated extraction methods compared. PF =PrepFiler Express BTA™ Forensic DNA Extraction Kit, (Thermo Fisher Scientific, Waltham, MA). EZ1 = EZ1 DNA Investigator (QIAGEN, Germantown, MD). | E12: Buccal cell suspension | F12: Non-porous | G12: Fired and unfired 9 mm brass ammunition casings. | H12: Yes | I12: Yes | J12: The micro-FLOQ® direct swabs failed to amplify any alleles. There was no statistical difference between the other methods or between fired and unfired ammunition. Recovered alleles for fired casings: 1st - BTMix rinse-and-swab 2nd - PF EDTA-Moistened CS. 3rd - EZ1 BTMix rinse-and-swab. Recovered alleles for unfired casings: 1st - BTMix rinse-and-swab 2nd - EZ1 BTMix rinse-and-swab. 3rd - PF EDTA-Moistened CS. | P12: =COUNTIF(Comparisons!$A:$A,A12)
A13: Dangsriwan et al., 2017 | B13: 80 (10) | C13: Tape-lifting. Swabbing. Direct lysis. | D13: No tape details. EO cotton swab (Thai Gauze, Thailand) nylon swab (Puritan nylon flocked swab by Puritan, USA). 3 wetting agents: PBS, DI water and Triton-X. No direct PCR details. | E13: Touch DNA | F13: Non-porous | G13: PVC pipe circuit board. | H13: Yes | I13: Yes | J13: The EO CS plus PBS wetting agent was the most efficient recovery method for both substrates (STR profiles), followed by the NS plus Triton-X for PVC pipe and nylon swab plus PBS for the circuit board. | P13: =COUNTIF(Comparisons!$A:$A,A13)
... A15: Giovanelli et al., 2021 | B15: 108 (36) | C15: Swabbing. | D15: PurFlock® swab (Puritan, USA). 4N6FLOQSwab® (Copan S.p.A., Italy). Cotton swab (Labor Import). | E15: Touch DNA | F15: Non-porous | G15: Vehicle surfaces (gear-knob, handbrake, steering wheel). | H15: Yes | I15: Yes | J15: Greater DNA recovery efficiency by the PurFlock® swab, followed by cotton, and then 4N6FLOQSwab® (p < 0.05). No significant difference among the surfaces analyzed. PurFlock® swab was more efficient for recovering donor alleles than the others. | P15: =COUNTIF(Comparisons!$A:$A,A15)
A16: Gunnarsson et al., 2009 | B16: 7908 | C16: Tape-lifting. Excising. | D16: TL manufactured in-house with a double-sided sticky tape. (EW150 (Eurocol Tape AB, Cstorp, Sweden) and sheets of colour laser transparency film 3M CG3720 (3M Visual Sys ems Division, Austin TX, USA). | E16: Various | F16: Porous Non-porous | G16: Various textiles. | H16: Yes | I16: Yes | J16: Number of amplified profiles was greater with TL than excision with less inhibition, even though there was significntly less DNA (p < 0.001). TL had more mixed profiles. TL covers larger surface area so mixes were expected. | P16: =COUNTIF(Comparisons!$A:$A,A16)
A17: Hansson et al., 2009 | B17: 24 (4) | C17: Tape-lifting. Swabbing. | D17: Scenesafe FAST™ minitape In-house water-soluble minitapes. cotton Dryswab™ (Medical Wire & Equipment), 4N6FLOQSwab® (COPANDiagnostics), Self-saturating swab (Puritan Medical Products Company). | E17: Touch DNA | F17: Porous Non-porous | G17: Porous: white cotton t shirts - tDNA collected from inside of neck. Non-porous: Screwdriver plastic handle. | H17: Not performed | I17: Yes | J17: Scenesafe FAST™ minitape (TL) had the highest tDNA recovery from fabrics. No differences were found between the swabs for DNA recovery from the fabric. For the plastic substrate, the self-saturating swab was more efficient than the other swabs. TL and the self-saturating swab had comparable DNA yields. However, the TL produced four full and one partial profile, and the self-saturating swab; one full and three partials. The water-soluble tapes were not suitable for Chelex extraction, and no statistical analyses were performed due to low replicate numbers. | P17: =COUNTIF(Comparisons!$A:$A,A17)
A18: Hartless et al., 2019 | B18: 160 (32) | C18: Swabbing. | D18: Cotton (Deltalab), Foam (Medical Wire), Polyester (Medical Wire). DS technique. | E18: Touch DNA | F18: Porous Non-porous | G18: Plastic handled screwdriver, aluminium cans, wooden handles, drink glass | H18: Yes | I18: Yes | J18: A significant difference was found between the substrate types and between the swab materials (p=0.031). The best STR profile results for each substrate were as follows: Wood: foam swab. Plastic: polyester. Aluminium can: cotton. Glass: cotton. | K18: The cotton swabs and Copan FLOQSwabs™ were the most efficient tools for DNA yield (p = 0.001). There was no significant difference between DS and SS methods. The TL performed the worst. | P18: =COUNTIF(Comparisons!$A:$A,A18)
A19: Hedman et al., 2020 | B19: 108 (2-6) | C19: Swabbing techniques. | D19: Selefa Cotton Tipped Applicator, ref. 120788. DS: 40 μL 0.9 % NaCl (two drops) was used to wet the tip of the first swab. The stains were covered twice with each swab held at approximately 45° followed by a dry swab. (processed separately). SWS v DS (wet-dry) techniques. | E19: Saliva | F19: Porous Non-porous | G19: Non-porous surfaces: window glass, PU leather, brass, steel, ridged plastic (Ikea cutting board). Porous surfaces: wood cutting board with veg oil, thick upholstery fabric. | H19: Yes | I19: No | J19: Wet SS of saliva was the most efficient for non-porous surfaces (p<0.001 to p = 0.014). A second dry swab is unneccessary as the first wet swab contains the most DNA with very little recovered from the second swab. This is consistent for most surfaces, however very complex porous substrates may benefit from DWS. For porous surfaces the DNA yield difference between the swabs was slightly less than for non-porous substrates, but still significant (p < 0.001). | P19: =COUNTIF(Comparisons!$A:$A,A19)
A20: Hedman et al., 2021 | B20: 363 ( 4 to 6) | C20: Swabbing. | D20: Cotton Tipped Applicator - Cotton (Selefa). Sterile Cotton Tipped Applicators Cotton (Puritan). Bode Crime Scene Collectors Cotton (Bode). 4N6FLOQSwab®, regular size tip, Crime Scene FLOQ Regular. 4N6FLOQSwab®, mini head tip, Crime Scene FLOQ® Mini. 4N6FLOQSwab®, regular size tip, Genetics FLOQ® Genetics. 4N6FLOQSwab®, Srk Pharma FLOQ® Pharma. Small foam: Sigma Virocult. Foam Tipped Applicators Foam (Puritan). Critical Swab, paddle-shaped foam head. Critical Swab, medium foam head. Large foam: Critical Swab, large rectangular foam head. Trace DNA Collection Swab. | E20: Saliva | F20: Porous Non-porous | G20: 1st exp. pt. 1 with all 13 swabs: Window glass, ridged plastic & wood. Pt. 2 included plastic bag, oilcloth, aluminium, steel, brass and leather. | H20: Yes | I20: No | J20: Window glass: All 13 swabs were equivalent. Ridged plastic: the large foam swabs had highest DNA yields (p <0.001), but not significant with Bonferoni post-hoc t-tests. Wood: large foam swabs were the most efficient, significant to the small foam swabs & Bode cotton swab (p < 0.0009). Four swabs were chosen as the best from each category for further testing. cotton: Selefa swab; nylon- flocked: FLOQ® Regular; small foam: Critical Medium; and large foam: Critical large rectangular (Macrofoam). 2x2cm sample area: Equivalent DNA yields for the swabs for these substrates: plastic bag, oilcloth, steel, brass and leather. Aluminium: Selefa CS and Critical Medium small foam swab gave higher amounts of DNA compared to the Macrofoam. 10x10cm sample area: glass: Selefa cotton swab ridged plastic: Macrofoam swab wood: Macrofoam swab (p < 0.0083). | P20: =COUNTIF(Comparisons!$A:$A,A20)
A21: Hess & Haas, 2017 | B21: 207 (3) | C21: Scraping. Tape-lifting. Swabbing. Swabbing techniques. | D21: Scenesafe FAST™ mini-tapes (Scenesafe Ltd., Birmingham, U.K.). Cotton (Prionics AG, Schlieren-Zurich, Switzerland) Dry and wet SS techniques. | E21: Touch DNA | F21: Porous | G21: Clothing: blue jeans, raincoats (synthetic, PVC coated fabric). dark synthetic fabrics, bright synthetic fabrics, dark coloured natural fibre clothing, light coloured natural fibre clothing. Bright fabrics: white, beige, light purple. Dark fabrics: black, dark purple, dark blue. | H21: Not performed | I21: Yes | J21: Scraping and TL were equal on DNA recovery from synthetic fabrics. Scraping outperformed TL on natural fibres and blue denim. Dry swabbing had the lowest STR recovery overall followed by wet swabbing. On the non-porous synthetic material, TL outperformed both swabbing techniques, (scraping was not tested). This material was the only substrate where dry swabbing outperformed wet swabbing. No difference was found between the colours of clothing, contrary to previous research and experience. | P21: =COUNTIF(Comparisons!$A:$A,A21)
A22: Hymus et al., 2024 | B22: 90 (3 & 4) | C22: Tape-lifting. | D22: Scotch® 183 Wall Safe Tape (S183), Scotch® 502 Sticky Tape and Scotch® (S502), Scotch® 600 Transparent Tape (S600), Scotch® Super-Hold Tape (S-Hold) (Scotch® Brand, MN, USA), Sellotape Strong Sticky Tape (Sello) (Henkel, Cheshire, UK), Lovell Surgical Solutions Clear Tape. | E22: Blood (1:10). Buccal cells (0.5ng/uL). Skin cells (brushed from skin with lint brush). | F22: Porous | G22: Tissue paper Lined paper Chux Towel Cotton canvas Printed chiffon Blue T-shirt Navy blue fleece Sweater knit Black knit scarf dark Indigo denim Black denim | H22: Yes | I22: Yes | J22: The lowest adhesion tape (scotch 183 wall safe tape) performed the best for STR profile quality in the comparison study with S-Hold. Higher ahesive tapes introduced PCR inhibitors - not from the adhesive itself as that was tested prior to the material sample testing, but from transfering fibres from the fabric substrate into the DNA extraction process. Highest DNA quantity results: Chux, canvas and chiffon: S183. Towel, knits and denim: S-Hold. Navy blue fleece: S183. The results were only statistically significant for the Chux and dark Indigo Denim (p < 0.05). | P22: =COUNTIF(Comparisons!$A:$A,A22)
A23: Kaesler et al., 2023 | B23: 160 (10 & 50) | C23: Swabbing techniques. | D23: 4N6FLOQSwab® (Thermo Fisher Scientific, Vic, AU). Wet DS, Modified rinse swab (RS), Single cumulative swab (grouped substrates CG1 & CG2). | E23: Touch DNA | F23: Non-porous | G23: Ten firearm components. A section of barrel; rifle stocks (synthetic and wooden); synthetic rifle foregrip (rubber); rifle magazine, scope, and bolt; two handgun grips (wooden and plastic); and a trigger. | H23: Yes | I23: Yes | J23: No significant difference overall in DNA yield between DS & RS or DS & CG2. DS significantly higher yield than RS for DNA recovery from the scope (p = 0.047), wooden stock (p = 0.021) & rubber foregrip (p = 0.048). | P23: =COUNTIF(Comparisons!$A:$A,A23)
A24: Kallupurackal et al., 2021 | B24: 175 (18 to 20) | C24: Tape-lifting. Swabbing. Swabbing techniques. | D24: Scene Safe FAST™ minitapes, Copan FLOQSwabs™ (SS - wet and dry). Cap- Shure sterile cotton- tipped (SS 5 methods, DS 1) Compared DS to SS methods | E24: Touch DNA | F24: Non-porous | G24: Skin | H24: Yes | I24: Yes | J24: The Cap- Shure cotton swabs and Copan FLOQSwabs™ were the most efficient tools. There was no significant difference between the DS and SS methods. The TL performed the worst with the least STR loci recovery. | P24: =COUNTIF(Comparisons!$A:$A,A24)
A25: Kanokwongnuwut et al., 2020 | B25: 63 (3) | C25: Tape-lifting. | D25: 14 tapes assessed. Only three suitable for direct STR profiling: brown packing tape (Packmate™), clear tape (Sellotape®), DNA-free tape (Lovell Surgical Solutions). | E25: Touch DNA (deposited by handling fabric for 15 sec.). | F25: Porous Non-porous | G25: 100% cotton. | H25: Yes | I25: Yes | J25: Diamond™ Dye (DD) was used to visualise the cellular material recovered from the adhesive tapes. Of the three tapes suitable for direct STR profiling, the brown packing tape recovered the most cellular material according to DD fluorescence cell counts. All three tapes produced comparable STR profiles without inhibition from the DD. Utilising DD staining to visualise cellular deposits may assist with assessing which samples should be prioritised for DNA profiling. | P25: =COUNTIF(Comparisons!$A:$A,A25)
A26: Kenna et al., 2011 | B26: 32 (16) | C26: Tape-lifting. Swabbing. | D26: Double-sided adhesive tape (Sellotape) mounted on one end of an acetate strip, 20 by 50 mm. Cotton swab - brand not listed. | E26: Saliva | F26: Non-porous | G26: Skin | H26: Yes | I26: No | J26: DNA yield was higher with TL than swabbing but had more variability in the replicates and was not statistically significant. | P26: =COUNTIF(Comparisons!$A:$A,A26)
A27: Kirgiz & Calloway, 2017 | B27: 140 (35 & 35) | C27: Tape-lifting. Swabbing. FTA paper-scraping. | D27: 3M™ Water-Soluble Wave Solder Tape 5414. Cotton-tipped swab (Fisherbrand®) DWS technique. | E27: Touch DNA | F27: Non-porous | G27: Hard plastic car steering wheels. | H27: Yes | I27: Yes | J27: No significant difference in DNA yield between TL and DS. FTA paper recovered significantly higher DNA than DS (p = 0.0051). Swabbing had more complete STR profiles compared to FTA paper and TL. Not statistically significant. | P27: =COUNTIF(Comparisons!$A:$A,A27)
A28: Kuffel et al., 2024 | B28: 108 (3) | C28: Excising. Swabbing. Swabbing techniques. Vacuum. | D28: Cotton swab (Technical Service Consultants Ltd. Lancashire, UK). | E28: Blood (bovine) Saliva cfDNA | F28: Porous | G28: Cotton: - dark green, 100 % cotton T-shirt, - red, 100 % cotton knitted jumper - yellow knitted cotton jumper composed of 65 % recycled cotton and 35 % virgin cotton. Paper: - white (80 g/m2), multi-purpose copier printer paper (Q-Connect, Belgium), - ECO TrendWhite, 100 % recycled, off-white (80 g/m2) printer paper (Steinbeis, Germany), - glossy leaflet paper - Filter Paper Fisherbrand® QL100 (Fisher Scientific, UK). Cardboard: - White, - Brown. | H28: Yes | I28: No | J28: Excision method was more efficient: Blood: green cotton (p = 0.006), glossy (p = 4.55E-04), off-white paper, filter paper & white cardboard had higher DNA yields but not significnt. Saliva: Red cotton (p = 0.002), all paper types. cfDNA & cellDNA: all cotton, off-white & glossy paper. Swabbing method more efficient: Blood : white paper, brown cardboard. Saliva: green cotton, brown cardboard. CellDNA: white paper (post-purification). cfDNA: Brown & white cardboard (pre & post-purification). No results were significant. Cell-free & cellular deposits eliminated PCR inhibitors found in bio-fluids. Differences in results could thus be deduced as substrate interaction. | P28: =COUNTIF(Comparisons!$A:$A,A28)
A29: Kwok et al., 2023 | B29: 240 (120) | C29: Tape-lifting. | D29: Black gelatine lifters (BVDA). Masking tape (Steris CorporationTM). | E29: Touch DNA | F29: Non-porous | G29: Glass slide (Fisher Brand) | H29: Not performed | I29: No | J29: Diamond™ Dye (DD) was used to visualise the cellular material recovered with the adhesive lifter and masking tape. No STR profiling was performed. The gelatine lifters had a higher fluorescence count than masking tape, therefore, it was assumed that they collected more cellular material than the masking tape for both natural and sebaceous deposits. The authors state that gelatine lifters are potentially useful for DNA recovery. However, they mention that black gelatine lifters may not be suitable due to potential PCR inhibitor presence and were used in this study for their ability to visualise the DD-stained material without background fluorescence observed with white and clear lifters. | P29: =COUNTIF(Comparisons!$A:$A,A29)
A30: Lim et al., 2016 | B30: 160 (10, 15 & 30) | C30: Tape-lifting. Swabbing. | D30: Mini-taping (WA Products, UK). Cotton swab, brand not noted. DS technique (wet-dry). | E30: Touch DNA Sweat Extracted DNA (Sweat & buccal cells). | F30: Non-porous | G30: Cable sheath | H30: Yes | I30: No | J30: No significant difference between TL and DS techniques. More complete profiles resulted from DNA recovery after cyanoacrylate fuming than with wet-powder suspension. | P30: =COUNTIF(Comparisons!$A:$A,A30)
... A40: Radojicic et al., 2018 | B40: 698 (119, 150 & 399) | C40: Swabbing Soaking | D40: Various | E40: Touch DNA | F40: Non-porous | G40: Various | H40: Yes | I40: Yes | J40: Retrospective casework study. Swabbing combined with AmpFLSTR® Identifiler Plus Kit produced the most informative STR profiles (allele count >12). This was statistically significant between the recovery methods (p = 0.019). There was no statistical difference between the amplification kits. | P40: =COUNTIF(Comparisons!$A:$A,A40)
A41: Seiberle et al., 2022 | B41: 576 (5 or 10) | C41: Swabbing | D41: ForensiX SafeDry, Copan 4N6FLOQSwab® Genetics. Copan 4N6FLOQSwab® Crime Scene. Sarstedt Forensic Swab. | E41: Human blood 1:10 Saliva neat Semen 1:10 Touch DNA | F41: Porous Non-porous | G41: Stone (Touch), wood (Touch), plastic knife-handle (Touch), knife-blade (Touch), glass slide (Touch), aluminium can (Touch), latex glove (Touch), plastic screwdriver (Touch), cotton T-Shirt (Touch), cotton T-Shirt (Semen), glass bottle (Saliva), synthetic, low pile carpet (Blood). | H41: Yes | I41: Yes | J41: The ForensiX SafeDry had the highest mean DNA yield for all biological materials across all substrates with a significant difference to both Copan swabs (p < 0.001) with the lowest allelic dropout. | K41: Some DNA profiles did not generate any alleles, even though DNA yields were reported. 1000 cells, no statistical difference between methods. 10,000 cells, no statistical significance was observed between all swab types and the spray-on rubber. Except for the large autosomal target (LAT), (p = 0.02921). 20,000 cells, the spray-on rubber coating recovered a significantly higher concentration than all swab types from the small (p = 0.02351) & large (p = 0.0337) autosomal targets. | P41: =COUNTIF(Comparisons!$A:$A,A41)
A42: Sessa et al., 2019 | B42: 240 (10) | C42: Tape-lifting Excising Swabbing | D42: Adhesive tape (Sirchie® Fingerprint Laboratories, Youngsville, NC,USA). Copan swab (Brescia, Italy). DSS method. | E42: Touch DNA | F42: Porous | G42: Bras | H42: Yes | I42: Yes | J42: No statistical differences between the methods. | P42: =COUNTIF(Comparisons!$A:$A,A42)
A43: Sterling et al., 2019 | B43: 20 (10) | C43: Tape-lifting Swabbing | D43: UV-irradiated tape (Neschen Foil S23, Voigtlaender, Blumberg, Germany). Fisherbrand sterile polyester swabs (Fisher Scientific, Hampton, NH). | E43: Touch DNA | F43: Non-porous | G43: Brass ammunition 9 mm | H43: Yes | I43: Yes | J43: The mean DNA yields were not significant, however the tape lifts had more samples over 1ng. 90% of donor pairs (1 TL, 1 S) had more DNA in the TL. STR comparisons showed the TL had 60% full or partial profiles whereas the swab had 50%. | P43: =COUNTIF(Comparisons!$A:$A,A43)
A44: Subhani et al., 2019 | B44: 40 (20) | C44: Swabbing Direct lysis | D44: Swab: wet-dry DS technique. Brand not noted. Direct lysis: semi-automated method with AutoLys tubes (Hamilton). | E44: Touch DNA | F44: Non-porous | G44: Brass 9mm ammunition. | H44: Yes | I44: Yes | J44: The direct lysis method recovered significantly more DNA and alleles than swabbing (p < 0.05). | P44: =COUNTIF(Comparisons!$A:$A,A44)
A45: Tasker et al., 2019 | B45: 120 (10) | C45: Swabbing | D45: Cotton swab (Puritan, Guilford, ME). MicroFLOQ® Direct Swab. | E45: Buccal cell suspension | F45: Non-porous | G45: PVC pipe galvanized steel pipe electrical tape copper wire. | H45: Yes | I45: Yes | J45: MicroFLOQ direct swabs recovered more alleles from all substrates with significantly higher peak heights (p < 0.01). The highest recovery was from electrical tape which was assumed to be due to the adhesive trapping more epithelial cells. | P45: =COUNTIF(Comparisons!$A:$A,A45)
A46: Tontarski et al., 2009 | B46: 72 | C46: Scraping Excising Swabbing | D46: Polyester swab (brand not noted). | E46: Blood | F46: Porous Non-porous | G46: wall (gypsum), ceiling (gypsum), floor (plywood), clothing, cutlery & crockery, furniture, glass. | H46: Not performed | I46: Yes | J46: A difference in allele count between the paired sets was found in 7 out of 36. Swab v cutting: in 3 sets the cutting had a higher number of alleles. In 2 sets the swabbing had higher. Swab v scraping: in two sets the scraping had a higher number of alleles. | P46: =COUNTIF(Comparisons!$A:$A,A46)
A47: Verdon et al., 2014 | B47: 28 (8) | C47: Tape-lifting | D47: Scotch Magic Tape. Scenesafe FAST™ minitapes. | E47: Touch DNA | F47: Porous | G47: Polyester strapping, cotton flnelette, cotton drill, plain polycotton. | H47: Yes | I47: Yes | J47: The mean DNA recovery was significantly higher with Scenesafe FAST™ than Scotch Magic (p < 0.005) for all fabrics. Scenesafe had higher recovery in all (1, 2, 4, 8, 16, 32, 64) tapings, except for the strapping with 64 tape-lifts. STR profiling results indicated that Scenesafe FAST™ had significantly higher allele counts from cotton, polyester strapping and polycotton, but no significant difference with flanelette. | K47: TL is more efficient for porous surfaces. Both methods are similar for non-porous surfaces. More alleles were detected for both dilutions from TL from porous surfaces. 1:50 dilution: TL significantly higher DNA yield for cotton and polyester (p < 0.05). The denim result was not significant, possibly due to the high variability in results. Similar results for each method for non-porous substrates. 1:100 dilution: TL significantly higher DNA yield for polyester and denim (p value not reported). Swabbing was significantly higher DNA yield for the tile (p < 0.05). | P47: =COUNTIF(Comparisons!$A:$A,A47)
A48: Verdon et al., 2014 (swabs) | B48: 560 (4) | C48: Swabbing | D48: Copan 150C. Bode Securswab. Puritan FABSWAB. Puritan 1PF Foam. Puritan Minipopule. Puritan 1PN Flock. Copan 4n6 Flock. MWE Polyester. MWE Rayon. Fitzco CEPSwab. | E48: Blood: neat & 1:50 Saliva: neat & 1:20 Touch DNA | F48: Porous Non-porous | G48: Glass Pitted plastic Wood Brick (or clay paver for touch DNA). | H48: Yes | I48: Yes | J48: Efficiency of the swab depended on the type of sample and substrate. The Puritan FABswab was first overall for combined collection & extraction efficiency of biological fluids. First for neat blood, second for dilute blood and neat saliva. The Puritan 1PF Foam ranked second overall for combined collection & extraction efficiency of biological fluids. First for neat saliva. The MWE Rayon ranked third overall for bio-fluid collection and extraction combined. First for dilute blood, second for dilute saliva, thrid for neat blood, and third for neat saliva. | P48: =COUNTIF(Comparisons!$A:$A,A48)
A49: Vickar et al., 2018 | B49: 64 (5 & 15) | C49: Swabbing Vacuum | D49: Cotton swab. Wet-dry DS technique. M-Vac®. | E49: Saliva Touch DNA | F49: Porous Non-porous | G49: Tile Brick | H49: Yes | I49: Yes | J49: Saliva Tiles: Double swabbing saliva yielded significantly more DNA on average than the M-Vac® (p < 0.05). Bricks: M-Vac® recovered significantly more DNA than double swabbing (p < 0.05). Touch DNA The M-Vac® collection resulted in a greater average number of true alleles but no significant differences between the methods, although the M-Vac® produced 50% more complete profiles. | P49: =COUNTIF(Comparisons!$A:$A,A49)
A50: Wahrer et al., 2023 | B50: 300 (12 & 24) | C50: Tape-lifting Swabbing Vacuum | D50: SceneSafe Fast™ Minitapes, SceneSafe, UK). ForensiX Collection Swab SafeDry (Prionics AG, Schlieren-Zürich, Switzerland). Wet (M-Vac®). Dry vacuum (DNA Buster). | E50: Touch DNA | F50: Porous Non-porous | G50: Carpet cotton sweater stone uncoated ceramic tile wood. | H50: Yes | I50: Yes | J50: Carpet: DNA yield highest for TL. This was signiicant compared to the DNA-Buster (p <0.01) and M-Vac® (p< 0.001). Full profiles were obtained for TL, Swab & dry vacuum. Sweater: DNA yield highest for M-Vac®, but was the most variable. Significant to SWS (p < 0.001), TL (p < 001). Full DNA profiles for TL, & both vacuums, but more complex mixtures with the vacuums. Stone: DNA yield highest for swabbing compared to tape (p < 0.01) and to both vacuums (p < 0.0001). There were significantly higher % full profiles for swab. Tile: Similar results to the stone substrate. Wood: TL had the highest DNA yield (significant to swab & DNA-buster) & significantly higher % full profiles. | P50: =COUNTIF(Comparisons!$A:$A,A50)
...

Sheet Comparisons
A1: author | B1: substrate_class | C1: biological_material_class | D1: better_method_class | E1: worse_method_class | F1: statistical_significance | G1: substrate_detail | H1: biological_material_detail | I1: better_recovery_method | J1: worse_recovery_method | K1: comparison_scope | L1: notes_source_result_summary
A2: Abdullah et al., 2023 | B2: Porous | C2: Blood | D2: Moist swab | E2: Wet swab / wet-dry swab / moist swab | F2: Significant (p < 0.01) | G2: 100% cotton | H2: Human blood / DNA solution | I2: Wet-moist double swab, 30 s | J2: Other swabbing techniques tested | K2: Swabbing-technique comparison | L2: Wet-moist double swabbing for 30 s produced significantly higher DNA yield from cotton.
A3: Abdullah et al., 2023 | B3: Non-porous | C3: Blood | D3: Equivalent / no clear better method | E3: Equivalent / no clear worse method | F3: Not significant | G3: Porcelain tile | H3: Human blood / DNA solution | I3: No clear better method | J3: No clear worse method | K3: Single-swab vs double-swab and duration comparison | L3: Swabbing duration for tile did not affect DNA yield, nor did single-swab vs double-swab method.
A4: Biggin et al., 2022 | B4: Porous | C4: Blood | D4: Other recovery method | E4: Other recovery method / swab, moisture unspecified | F4: Not performed | G4: Snow | H4: Human blood, neat | I4: Untreated filter paper | J4: FTA paper-scraping and cotton swab | K4: Swab vs FTA paper-scraping vs untreated filter paper | L4: All methods produced full STR profiles; filter paper had highest mean DNA yield, followed by FTA, then swabs.
A5: Biggin et al., 2022 | B5: Porous | C5: Blood | D5: Other recovery method | E5: Swab, moisture unspecified | F5: Not performed | G5: Snow | H5: Human blood, neat | I5: FTA paper-scraping | J5: Cotton swab | K5: FTA paper-scraping vs swab | L5: FTA mean DNA yield exceeded swab mean DNA yield; no statistical analyses performed.
A6: Blackmore et al., 2024 | B6: Porous | C6: Saliva | D6: Tape lift | E6: Swab, moisture unspecified / other recovery method | F6: Statistical analysis performed; pairwise p-value not stated in source summary | G6: 100% polypropylene carpet, 1:40 saliva dilution | H6: Saliva 1:40 | I6: Tape lift | J6: Swab and M-Vac | K6: Tape lift vs swab vs vacuum | L6: Closest mean SAT for saliva on carpet at 1:40 dilution was tape lift.
A7: Blackmore et al., 2024 | B7: Porous | C7: Saliva | D7: Other recovery method | E7: Tape lift / swab, moisture unspecified | F7: Statistical analysis performed; pairwise p-value not stated in source summary | G7: 100% polypropylene carpet, 1:160 saliva dilution | H7: Saliva 1:160 | I7: M-Vac | J7: Tape lift and swab | K7: Tape lift vs swab vs vacuum | L7: Closest mean SAT for saliva on carpet at 1:160 dilution was M-Vac.
A8: Blackmore et al., 2024 | B8: Non-porous | C8: Saliva | D8: Tape lift | E8: Swab, moisture unspecified / other recovery method | F8: Statistical analysis performed; pairwise p-value not stated in source summary | G8: Brick, 1:40 saliva dilution | H8: Saliva 1:40 | I8: Tape lift | J8: Swab and M-Vac | K8: Tape lift vs swab vs vacuum | L8: Closest result for saliva on brick at 1:40 dilution was tape lift; amplified 11 alleles.
A9: Blackmore et al., 2024 | B9: Porous | C9: Touch DNA | D9: Tape lift | E9: Swab, moisture unspecified / other recovery method | F9: Statistical analysis performed; pairwise p-value not stated in source summary | G9: Car boot carpet | H9: Touch DNA | I9: Tape lift | J9: Swab and M-Vac | K9: Tape lift vs swab vs vacuum | L9: Closest mean SAT for touch DNA on car boot carpet was tape lift.
A10: Blackmore et al., 2024 | B10: Porous | C10: Touch DNA | D10: Other recovery method | E10: Tape lift / swab, moisture unspecified | F10: Statistical analysis performed; pairwise p-value not stated in source summary | G10: T-shirt submerged in creek for 5 days | H10: Touch DNA | I10: M-Vac | J10: Tape lift and swab | K10: Tape lift vs swab vs vacuum | L10: Closest mean SAT for touch DNA on T-shirt was M-Vac.
A11: Bonsu et al., 2021a | B11: Non-porous | C11: Outside requested categories | D11: Moist swab | E11: Moist swab | F11: Significant | G11: Brass; copper; steel; plastic | H11: Purified gDNA, 20 ng | I11: Isohelix swab | J11: Puritan rayon swab | K11: Isohelix vs Puritan rayon swab; both moist double swab technique | L11: Isohelix recovered 74% DNA vs 50% for Puritan rayon across substrates.
A12: Bonsu et al., 2021b | B12: Non-porous | C12: Touch DNA | D12: Wet swab | E12: Wet swab | F12: Significant | G12: Brass; aluminium bathroom door; stainless steel tap | H12: Touch DNA | I12: Isohelix swab | J12: Puritan rayon swab | K12: Isohelix vs Puritan rayon wet single swab | L12: Isohelix recovered significantly more DNA for all metals except aluminium office door handle.
... A134: Williams et al., 2015 | B134: Non-porous | C134: Saliva | D134: Equivalent / no clear better method | E134: Equivalent / no clear worse method | F134: Not significant | G134: Skin | H134: Saliva | I134: No clear better method | J134: No clear worse method | K134: Moist-dry double swab vs M-Vac | L134: No significant differences between methods or skin locations; similar number of profiles obtained.

Sheet README
A1: Field | B1: Meaning
A2: Workbook purpose | B2: Single review workbook combining publication-level study details with the reviewed structured comparison rows used by the decision map.
A3: studies sheet | B3: One row per source publication. The comparison_count helper column counts Comparisons rows by matching author.
A4: Comparisons sheet | B4: One row per curated method comparison. author identifies the source study and links back to the matching row in the studies sheet.
A5: Source study workbook | B5: /home/paul/wk/frdb/interactive_evidence_recovery_comparison_results.xlsx
A6: Source study workbook SHA-256 | B6: 4ae0b076651c0c135a6c1b8bff33e99d53ba4507e3f393d6876167a4d0257f34
A7: Source comparison workbook | B7: /home/paul/wk/frdb/recovery_comparisons.xlsx
A8: Source comparison workbook SHA-256 | B8: ccc86f6a20b4216d1fe99b72d9c587ff085b92e68bb50a59e5356b6680e39eb2
A9: Study rows | B9: 50
A10: Comparison rows | B10: 133
A11: Duplicate comparison rows removed | B11: 0
A12: Validation | B12: Every comparison author exists in studies, study authors are unique, and every study has at least one comparison row.
